<?xml version="1.0" ?>
<!-- =================================================================================== -->
<!-- |    This document was autogenerated by xacro from ./src/experiment_settings/urdf/ur5e_sim.xacro | -->
<!-- |    EDITING THIS FILE BY HAND IS NOT RECOMMENDED                                 | -->
<!-- =================================================================================== -->
<robot name="ur5e_robot" xmlns:xacro="http://wiki.ros.org/xacro">

    <arg name="prefix" default="" />
    <arg name="pi" default="3.1415"/>
    <arg name="safety_limits" default="false"/>
    <arg name="0.15" default="0.15"/>
    <arg name="safety_k_position" default="20"/>
    
    <arg name="base_visual_mesh" default="./ur5e_description/meshes/ur5e/visual/base.dae"/>
    <arg name="base_visual_material_name" default="LightGrey"/>
    <arg name="base_visual_material_color" default="0.7 0.7 0.7 1.0" />
    <arg name="base_collision_mesh" default="./ur5e_description/meshes/ur5e/collision/base.stl"/>
    <arg name="base_inertia_radius" default="0.06"/>
    <arg name="base_inertia_length" defaul="0.05"/>
    <arg name="base_mass" default="4"/>

    <arg name="shoulder_visual_mesh" default="./ur5e_description/meshes/ur5e/visual/shoulder.dae"/>
    <arg name="shoulder_visual_material_name" default="LightGrey"/>
    <arg name="shoulder_visual_material_color" default="0.7 0.7 0.7 1.0" />
    <arg name="shoulder_collision_mesh" default="./ur5e_description/meshes/ur5e/collision/shoulder.stl"/>
    <arg name="shoulder_inertia_radius" default="0.06"/>
    <arg name="shoulder_inertia_length" default="0.15"/>
    <arg name="shoulder_mass" default="3.7"/>


    <arg name="shoulder_offset" default="0.138"/>

    <arg name="upper_arm_visual_mesh" default="./ur5e_description/meshes/ur5e/visual/upperarm.dae"/>
    <arg name="upper_arm_visual_material_name" default="LightGrey"/>
    <arg name="upper_arm_visual_material_color" default="0.7 0.7 0.7 1.0" />
    <arg name="upper_arm_collision_mesh" default="./ur5e_description/meshes/ur5e/collision/upperarm.stl"/>
    <arg name="upperarm_inertia_radius" default="0.06"/>
    <arg name="upperarm_inertia_length" default="0.425"/>
    <arg name="upper_arm_mass" default="8.393"/>
    <arg name="upper_arm_inertia_offset" default="0.138"/>


    <arg name="elbow_offset" default="0.007"/>

    <arg name="forearm_visual_mesh" default="./ur5e_description/meshes/ur5e/visual/forearm.dae"/>
    <arg name="forearm_visual_material_name" default="LightGrey"/>
    <arg name="forearm_visual_material_color" default="0.7 0.7 0.7 1.0" />
    <arg name="forearm_collision_mesh" default="./ur5e_description/meshes/ur5e/collision/forearm.stl"/>
    <arg name="forearm_inertia_radius" default="0.06"/>
    <arg name="forearm_inertia_length" default="0.3922"/>
    <arg name="forearm_mass" default="2.275"/>
    <arg name="elbow_inertia_offset" default="0.007"/>


    <arg name="wrist_1_visual_offset" default="-0.127"/>

    <arg name="wrist_1_visual_mesh" default="./ur5e_description/meshes/ur5e/visual/wrist1.dae"/>
    <arg name="wrist_1_visual_material_name" default="LightGrey"/>
    <arg name="wrist_1_visual_material_color" default="0.7 0.7 0.7 1.0" />
    <arg name="wrist_1_collision_mesh" default="./ur5e_description/meshes/ur5e/collision/wrist1.stl"/>
    <arg name="wrist_1_inertia_radius" default="0.06"/>
    <arg name="wrist_1_inertia_length" default="0.12"/>
    <arg name="wrist_1_mass" default="1.2190"/>


    <arg name="wrist_2_visual_offset" default="-0.0997"/>

    <arg name="wrist_2_visual_mesh" default="./ur5e_description/meshes/ur5e/visual/wrist2.dae"/>
    <arg name="wrist_2_visual_material_name" default="LightGrey"/>
    <arg name="wrist_2_visual_material_color" default="0.7 0.7 0.7 1.0" />
    <arg name="wrist_2_collision_mesh" default="./ur5e_description/meshes/ur5e/collision/wrist2.stl"/>
    <arg name="wrist_2_inertia_radius" default="0.06"/>
    <arg name="wrist_2_inertia_length" default="0.12"/>
    <arg name="wrist_2_mass" default="1.2190"/>


    <arg name="wrist_3_visual_offset" default="-0.0989"/>

    <arg name="wrist_3_visual_mesh" default="./ur5e_description/meshes/ur5e/visual/wrist3.dae"/>
    <arg name="wrist_3_visual_material_name" default="LightGrey"/>
    <arg name="wrist_3_visual_material_color" default="0.7 0.7 0.7 1.0" />
    <arg name="wrist_3_collision_mesh" default="./ur5e_description/meshes/ur5e/collision/wrist3.stl"/>
    <arg name="wrist_3_inertia_radius" default="0.0375"/>
    <arg name="wrist_3_inertia_length" default="0.0458"/>
    <arg name="wrist_3_mass" default="0.1879"/>

    

    <link name="base_link">
        <inertial>
            <mass value="0.0" />
            <origin xyz="0.0 0.0 0.0"/>
            <inertia ixx="0.0" ixy="0.0" ixz="0.0" iyy="0.0" iyz="0.0" izz="0.0" />
        </inertial>
    </link>
    <link name="base_link_inertia">
        <visual>
        <origin xyz="0 0 0" rpy="0 0 3.1415"/>
        <geometry>
            <mesh filename="./ur5e_description/meshes/ur5e/visual/base.dae"/>
        </geometry>
        <material name="LightGrey">
            <color rgba="0.7 0.7 0.7 1.0"/>
        </material>
        </visual>
        <collision>
        <origin xyz="0 0 0" rpy="0 0 3.1415"/>
        <geometry>
            <mesh filename="./ur5e_description/meshes/ur5e/collision/base.stl"/>
        </geometry>
        </collision>

        <inertial>
            <mass value="4.0" />
            <origin xyz="0.0 0.0 0.0"/>
            <inertia ixx="0.0833333 * 4.0 * (3 * 0.06 * 0.06 + 0.05 * 0.05)" ixy="0.0" ixz="0.0"
                iyy="0.0833333 * 4.0 * (3 * 0.06 * 0.06 + 0.05 * 0.05)" iyz="0.0"
                izz="0.5 * 4.0 * 0.06 * 0.06" />
        </inertial>
    </link>
    <link name="shoulder_link">
        <visual>
        <origin xyz="0 0 0" rpy="0 0 3.1415"/>
        <geometry>
            <mesh filename="./ur5e_description/meshes/ur5e/visual/shoulder.dae"/>
        </geometry>
        <material name="LightGrey">
            <color rgba="0.7 0.7 0.7 1.0"/>
        </material>
        </visual>
        <collision>
        <origin xyz="0 0 0" rpy="0 0 3.1415"/>
        <geometry>
            <mesh filename="./ur5e_description/meshes/ur5e/collision/shoulder.stl"/>
        </geometry>
        </collision>
        <inertial>
            <mass value="3.7" />
            <origin xyz="0.0 0.00193 -0.02561"/>
            <inertia ixx="0.0833333 * 3.7 * (3 * 0.06 * 0.06 + 0.15 * 0.15)" ixy="0.0" ixz="0.0"
                iyy="0.0833333 * 3.7 * (3 * 0.06 * 0.06 + 0.15 * 0.15)" iyz="0.0"
                izz="0.5 * 3.7 * 0.06 * 0.06" />
        </inertial>
    </link>
    <link name="upper_arm_link">
        <visual>
        <origin xyz="0 0 0.138" rpy="1.5708 0 -1.5708"/>
        <geometry>
            <mesh filename="./ur5e_description/meshes/ur5e/visual/upperarm.dae"/>
        </geometry>
        <material name="LightGrey">
            <color rgba="0.7 0.7 0.7 1.0"/>
        </material>
        </visual>
        <collision>
        <origin xyz="0 0 0.138" rpy="1.5708 0 -1.5708"/>
        <geometry>
            <mesh filename="./ur5e_description/meshes/ur5e/collision/upperarm.stl"/>
        </geometry>
        </collision>
        <inertial>
            <mass value="8.393" />
            <origin xyz="0.0 -0.024201 0.2125"/>
            <inertia ixx="0.0833333 * 8.393 * (3 * 0.06 * 0.06 + 0.425 * 0.425)" ixy="0.0" ixz="0.0"
                iyy="0.0833333 * 8.393 * (3 * 0.06 * 0.06 + 0.425 * 0.425)" iyz="0.0"
                izz="0.5 * 8.393 * 0.06 * 0.06" />
        </inertial>
    </link>
    <link name="forearm_link">
        <visual>
        <origin xyz="0 0 0.007" rpy="1.5708 0 -1.5708"/>
        <geometry>
            <mesh filename="./ur5e_description/meshes/ur5e/visual/forearm.dae"/>
        </geometry>
        <material name="LightGrey">
            <color rgba="0.7 0.7 0.7 1.0"/>
        </material>
        </visual>
        <collision>
        <origin xyz="0 0 0.007" rpy="1.5708 0 -1.5708"/>
        <geometry>
            <mesh filename="./ur5e_description/meshes/ur5e/collision/forearm.stl"/>
        </geometry>
        </collision>
        <inertial>
            <mass value="2.275" />
            <origin xyz="0.0 0.0265 0.11993"/>
            <inertia ixx="0.0833333 * 2.275 * (3 * 0.06 * 0.06 + 0.3922 * 0.3922)" ixy="0.0" ixz="0.0"
                iyy="0.0833333 * 2.275 * (3 * 0.06 * 0.06 + 0.3922 * 0.3922)" iyz="0.0"
                izz="0.5 * 2.275 * 0.06 * 0.06" />
        </inertial>
    </link>
    <link name="wrist_1_link">
        <visual>
        <origin xyz="0 0 -0.127" rpy="1.5708 0 0"/>
        <geometry>
            <mesh filename="./ur5e_description/meshes/ur5e/visual/wrist1.dae"/>
        </geometry>
        <material name="LightGrey">
            <color rgba="0.7 0.7 0.7 1.0"/>
        </material>
        </visual>
        <collision>
        <origin xyz="0 0 -0.127" rpy="1.5708 0 0"/>
        <geometry>
            <mesh filename="./ur5e_description/meshes/ur5e/collision/wrist1.stl"/>
        </geometry>
        </collision>
        <inertial>
            <mass value="1.2190" />
            <origin xyz="0.0 0.110949 0.01634"/>
            <inertia ixx="0.0833333 * 1.2190 * (3 * 0.06 * 0.06 + 0.12 * 0.12)" ixy="0.0" ixz="0.0"
                iyy="0.0833333 * 1.2190 * (3 * 0.06 * 0.06 + 0.12 * 0.12)" iyz="0.0"
                izz="0.5 * 1.2190 * 0.06 * 0.06" />
        </inertial>
    </link>
    <link name="wrist_2_link">
        <visual>
        <origin xyz="0 0 -0.0997" rpy="0 0 0"/>
        <geometry>
            <mesh filename="./ur5e_description/meshes/ur5e/visual/wrist2.dae"/>
        </geometry>
        <material name="LightGrey">
            <color rgba="0.7 0.7 0.7 1.0"/>
        </material>
        </visual>
        <collision>
        <origin xyz="0 0 -0.0997" rpy="0 0 0"/>
        <geometry>
            <mesh filename="./ur5e_description/meshes/ur5e/collision/wrist2.stl"/>
        </geometry>
        </collision>
        <inertial>
            <mass value="1.219" />
            <origin xyz="0.0 0.0018 0.11099"/>
            <inertia ixx="0.0833333 * 1.219 * (3 * 0.06 * 0.06 + 0.12 * 0.12)" ixy="0.0" ixz="0.0"
                iyy="0.0833333 * 1.219 * (3 * 0.06 * 0.06 + 0.12 * 0.12)" iyz="0.0"
                izz="0.5 * 1.219 * 0.06 * 0.06" />
        </inertial>
    </link>
    <link name="wrist_3_link">
        <visual>
        <origin xyz="0 0 -0.0989" rpy="1.5708 0 0"/>
        <geometry>
            <mesh filename="./ur5e_description/meshes/ur5e/visual/wrist3.dae"/>
        </geometry>
        <material name="LightGrey">
            <color rgba="0.7 0.7 0.7 1.0"/>
        </material>
        </visual>
        <collision>
        <origin xyz="0 0 -0.0989" rpy="1.5708 0 0"/>
        <geometry>
            <mesh filename="./ur5e_description/meshes/ur5e/collision/wrist3.stl"/>
        </geometry>
        </collision>
        <inertial>
            <mass value="0.1879" />
            <origin xyz="0.0 0.001159 0.0"/>
            <inertia ixx="0.0833333 * 0.1879 * (3 * 0.0375 * 0.0375 + 0.0458 * 0.0458)" ixy="0.0" ixz="0.0"
                iyy="0.0833333 * 0.1879 * (3 * 0.0375 * 0.0375 + 0.0458 * 0.0458)" iyz="0.0"
                izz="0.5 * 0.1879 * 0.0375 * 0.0375" />
        </inertial>
    </link>



    <arg name="shoulder_x" default="0"/>
    <arg name="shoulder_y" default="0"/>
    <arg name="shoulder_z" default="0.1625"/>
    <arg name="shoulder_roll" default="0"/>
    <arg name="shoulder_pitch" default="0"/>
    <arg name="shoulder_yaw" default="0"/>
    <arg name="shoulder_pan_lower_limit" default="-2*3.1415"/>
    <arg name="shoulder_pan_upper_limit" default="2*{pi}"/>
    <arg name="shoulder_pan_effort_limit" default="150"/>
    <arg name="shoulder_pan_velocity_limit" default="180"/>

    <arg name="upper_arm_x" default="0"/>
    <arg name="upper_arm_y" default="0"/>
    <arg name="upper_arm_z" default="0"/>
    <arg name="upper_arm_roll" default="1.570796327"/>
    <arg name="upper_arm_pitch" default="0"/>
    <arg name="upper_arm_yaw" default="0"/>
    <arg name="shoulder_lift_lower_limit" default="-2*3.1415"/>
    <arg name="shoulder_lift_upper_limit" default="2*{pi}"/>
    <arg name="shoulder_lift_effort_limit" default="150"/>
    <arg name="shoulder_lift_velocity_limit" default="180"/>
    
    <arg name="forearm_x" default="-0.425"/>
    <arg name="forearm_y" default="0"/>
    <arg name="forearm_z" default="0.0"/>
    <arg name="forearm_roll" default="0"/>
    <arg name="forearm_pitch" default="0"/>
    <arg name="forearm_yaw" default="0"/>
    <arg name="elbow_lower_limit" default="-3.1415"/>
    <arg name="elbow_upper_limit" default="{pi}"/>
    <arg name="elbow_effort_limit" default="150"/>
    <arg name="elbow_velocity_limit" default="180"/>

    <arg name="wrist_1_x" default="-0.3922"/>
    <arg name="wrist_1_y" default="0"/>
    <arg name="wrist_1_z" default="0.1333"/>
    <arg name="wrist_1_roll" default="0"/>
    <arg name="wrist_1_pitch" default="0"/>
    <arg name="wrist_1_yaw" default="0"/>
    <arg name="wrist_1_lower_limit" default="-2*3.1415"/>
    <arg name="wrist_1_upper_limit" default="2*{pi}"/>
    <arg name="wrist_1_effort_limit" default="28"/>
    <arg name="wrist_1_velocity_limit" default="180"/>

    <arg name="wrist_2_x" default="0.0"/>
    <arg name="wrist_2_y" default="-0.0997"/>
    <arg name="wrist_2_z" default="-2.044881182297852e-11"/>
    <arg name="wrist_2_roll" default="1.570796327"/>
    <arg name="wrist_2_pitch" default="0"/>
    <arg name="wrist_2_yaw" default="0"/>
    <arg name="wrist_2_lower_limit" default="-2*3.1415"/>
    <arg name="wrist_2_upper_limit" default="2*{pi}"/>
    <arg name="wrist_2_effort_limit" default="28"/>
    <arg name="wrist_2_velocity_limit" default="180"/>

    <arg name="wrist_3_x" default="0.0"/>
    <arg name="wrist_3_y" default="0.09959999999999999"/>
    <arg name="wrist_3_z" default="-2.042830148012698e-11"/>
    <arg name="wrist_3_roll" default="1.570796326589793"/>
    <arg name="wrist_3_pitch" default="3.141592653589793"/>
    <arg name="wrist_3_yaw" default="3.141592653589793"/>
    <arg name="wrist_3_lower_limit" default="-2*3.1415"/>
    <arg name="wrist_3_upper_limit" default="2*{pi}"/>
    <arg name="wrist_3_effort_limit" default="28"/>
    <arg name="wrist_3_velocity_limit" default="180"/>

    <!-- joints: main serial chain -->
    <joint name="base_link-base_link_inertia" type="fixed">
        <parent link="base_link" />
        <child link="base_link_inertia" />
        <!-- 'base_link' is REP-103 aligned (so X+ forward), while the internal
            frames of the robot/controller have X+ pointing backwards.
            Use the joint between 'base_link' and 'base_link_inertia' (a dummy
            link/frame) to introduce the necessary rotation over Z (of pi rad).
        -->
        <origin xyz="0 0 0" rpy="0 0 3.1415" />
    </joint>
    <joint name="shoulder_pan_joint" type="revolute">
        <parent link="base_link_inertia" />
        <child link="shoulder_link" />
        <origin xyz="0 0 0.1625" rpy="0 0 0" />
        <axis xyz="0 0 1" />
        <limit lower="-6.2831" upper="6.2831"
        effort="150" velocity="180"/>
        <xacro:if value="false">
            <safety_controller soft_lower_limit="-6.2831 + 0.15" soft_upper_limit="6.2831 - 0.15" k_position="20" k_velocity="0.0"/>
        </xacro:if>
        <dynamics damping="0" friction="0"/>
    </joint>
    <joint name="shoulder_lift_joint" type="revolute">
        <parent link="shoulder_link" />
        <child link="upper_arm_link" />
        <origin xyz="0 0 0" rpy="1.570796327 0 0" />
        <axis xyz="0 0 1" />
        <limit lower="-6.2831" upper="6.2831"
        effort="150" velocity="180"/>
        <xacro:if value="false">
            <safety_controller soft_lower_limit="-6.2831 + 0.15" soft_upper_limit="6.2831 - 0.15}" k_position="20" k_velocity="0.0"/>
        </xacro:if>
        <dynamics damping="0" friction="0"/>
    </joint>
    <joint name="elbow_joint" type="revolute">
        <parent link="upper_arm_link" />
        <child link="forearm_link" />
        <origin xyz="-0.425 0 0" rpy="0 0 0" />
        <axis xyz="0 0 1" />
        <limit lower="-3.1415" upper="3.1415"
        effort="150" velocity="180"/>
        <xacro:if value="false">
            <safety_controller soft_lower_limit="-3.1415 + 0.15" soft_upper_limit="3.1415 - 0.15" k_position="20" k_velocity="0.0"/>
        </xacro:if>
        <dynamics damping="0" friction="0"/>
    </joint>
    <joint name="wrist_1_joint" type="revolute">
        <parent link="forearm_link" />
        <child link="wrist_1_link" />
        <origin xyz="-0.3922 0 0.1333" rpy="0 0 0" />
        <axis xyz="0 0 1" />
        <limit lower="-6.2831" upper="6.2831"
        effort="28" velocity="180"/>
        <xacro:if value="false">
            <safety_controller soft_lower_limit="-6.2831 + 0.15" soft_upper_limit="6.2831 - 0.15" k_position="20" k_velocity="0.0"/>
        </xacro:if>
        <dynamics damping="0" friction="0"/>
    </joint>
    <joint name="wrist_2_joint" type="revolute">
        <parent link="wrist_1_link" />
        <child link="wrist_2_link" />
        <origin xyz="0 -0.0997 -2.044881182297852e-11" rpy="1.570796327 0 0" />
        <axis xyz="0 0 1" />
        <limit lower="-6.2831" upper="6.2831"
                effort="28" velocity="180"/>
        <xacro:if value="false">
            <safety_controller soft_lower_limit="-6.2831 + 0.15" soft_upper_limit="6.2831 - 0.15" k_position="20" k_velocity="0.0"/>
        </xacro:if>
        <dynamics damping="0" friction="0"/>
    </joint>
    <joint name="wrist_3_joint" type="revolute">
        <parent link="wrist_2_link" />
        <child link="wrist_3_link" />
        <origin xyz="0 0.09959999999999999 -2.042830148012698e-11" rpy="1.570796326589793 3.141592653589793 3.141592653589793" />
        <axis xyz="0 0 1" />
        <limit lower="-6.2831" upper="6.2831"
                effort="28" velocity="180"/>
        <xacro:if value="false">
            <safety_controller soft_lower_limit="-6.2831 + 0.15" soft_upper_limit="6.2831 - 0.15" k_position="20" k_velocity="0.0"/>
        </xacro:if>
        <dynamics damping="0" friction="0"/>
    </joint>

    <!-- ROS-Industrial 'base' frame: base_link to UR 'Base' Coordinates transform -->
    <link name="base">
        <inertial>
            <mass value="0.0" />
            <origin xyz="0.0 0.0 0.0"/>
            <inertia ixx="0.0" ixy="0.0" ixz="0.0" iyy="0.0" iyz="0.0" izz="0.0" />
        </inertial>
    </link>
    <joint name="base_link-base_fixed_joint" type="fixed">
        <!-- Note the rotation over Z of pi radians: as base_link is REP-103
            aligned (ie: has X+ forward, Y+ left and Z+ up), this is needed
            to correctly align 'base' with the 'Base' coordinate system of
            the UR controller.
        -->
        <origin xyz="0 0 0" rpy="0 0 3.1415"/>
        <parent link="base_link"/>
        <child link="base"/>
    </joint>

    <!-- ROS-Industrial 'flange' frame: attachment point for EEF models -->
    <link name="flange" >
        <inertial>
            <mass value="0.0" />
            <origin xyz="0.0 0.0 0.0"/>
            <inertia ixx="0.0" ixy="0.0" ixz="0.0" iyy="0.0" iyz="0.0" izz="0.0" />
        </inertial>
    </link>
    <joint name="wrist_3-flange" type="fixed">
        <parent link="wrist_3_link" />
        <child link="flange" />
        <origin xyz="0 0 0" rpy="0 -1.5708 -1.5708" />
    </joint>

    <!-- ROS-Industrial 'tool0' frame: all-zeros tool frame -->
    <link name="tool0">
        <inertial>
            <mass value="0.0" />
            <origin xyz="0.0 0.0 0.0"/>
            <inertia ixx="0.0" ixy="0.0" ixz="0.0" iyy="0.0" iyz="0.0" izz="0.0" />
        </inertial>
    </link>
    <joint name="flange-tool0" type="fixed">
        <!-- default toolframe: X+ left, Y+ up, Z+ front -->
        <origin xyz="0 0 0" rpy="1.5708 0 1.5708"/>
        <parent link="flange"/>
        <child link="tool0"/>
    </joint>

    <link name="ee_link">
        <inertial>
            <mass value="0.0" />
            <origin xyz="0.0 0.0 0.0"/>
            <inertia ixx="0.0" ixy="0.0" ixz="0.0" iyy="0.0" iyz="0.0" izz="0.0" />
        </inertial>
    </link>
    <joint name="tool0_ee_link" type="fixed">
        <parent link="tool0"/>
        <child link="ee_link"/>
        <origin xyz="0 0 0" rpy="0 0 0"/>
    </joint>

    <material name="camera_aluminum">
        <color rgba="0.5 0.5 0.5 1"/>
    </material>

  
  <!-- other elements -->
  <link name="base_cylinder">
    <origin rpy="0 0 0" xyz="0 0 0"/>
    <visual>
      <geometry>
        <cylinder length="0.70" radius="0.2"/>
      </geometry>
      <material name="grey"/>
    </visual>
    <colision>
      <geometry>
        <cylinder length="0.70" radius="0.2"/>
      </geometry>
    </colision>
    <inertial>
        <mass value="0.0" />
        <origin xyz="0.0 0.0 0.0"/>
        <inertia ixx="0.0" ixy="0.0" ixz="0.0" iyy="0.0" iyz="0.0" izz="0.0" />
    </inertial>
  </link>
  



  <!-- construction -->
  <link name="world">
    <inertial>
            <mass value="0.0" />
            <origin xyz="0.0 0.0 0.0"/>
            <inertia ixx="0.0" ixy="0.0" ixz="0.0" iyy="0.0" iyz="0.0" izz="0.0" />
        </inertial>
    </link>
  
  <joint name="world_base_joint" type="fixed">
    <parent link="world"/>
    <child link="base_cylinder"/>
    <origin rpy="0.0 0.0 0.0" xyz="0.0 0.0 0.35"/>
  </joint>
  <joint name="base_robot_joint" type="fixed">
    <parent link="base_cylinder"/>
    <child link="base_link"/>
    <origin rpy="0.0 0.0 -1.57" xyz="0.0 0.0 0.35"/>
  </joint>

  <!-- <joint name="world_table_joint" type="fixed">
    <parent link="world"/>
    <child link="table"/>
    <origin rpy="-1.57 0.0 -1.57" xyz="-0.2 1.0 0.74"/>
  </joint> -->



    <link name="camera_link">
        <visual>
        <origin rpy="1.5707963267948966 0 1.5707963267948966" xyz="0.0149 -0.0175 0"/>
        <geometry>
            <!-- <box size="${d435_cam_width} ${d435_cam_height} ${d435_cam_depth}"/> -->
            <mesh filename="./realsense_description/meshes/d435.dae"/>
            <!--<mesh filename="package://realsense2_description/meshes/d435/d435.dae" />-->
        </geometry>
        <material name="camera_aluminum"/>
        </visual>
        <collision>
        <origin rpy="0 0 0" xyz="0 -0.0175 0"/>
        <geometry>
            <box size="0.02505 0.09 0.025"/>
        </geometry>
        </collision>
        <inertial>
        <!-- The following are not reliable values, and should not be used for modeling -->
        <mass value="0.564"/>
        <origin xyz="0 0 0"/>
        <inertia ixx="0.003881243" ixy="0.0" ixz="0.0" iyy="0.000498940" iyz="0.0" izz="0.003879257"/>
        </inertial>
    </link>

  <!-- camera depth joints and links -->
  <joint name="camera_depth_joint" type="fixed">
    <origin rpy="0 0 0" xyz="0 0 0"/>
    <parent link="camera_link"/>
    <child link="camera_depth_frame"/>
  </joint>

  <link name="camera_depth_frame">
    <inertial>
        <mass value="0.0" />
        <origin xyz="0.0 0.0 0.0"/>
        <inertia ixx="0.0" ixy="0.0" ixz="0.0" iyy="0.0" iyz="0.0" izz="0.0" />
    </inertial>
  </link>

  <joint name="camera_depth_optical_joint" type="fixed">
    <origin rpy="-1.5707963267948966 0 -1.5707963267948966" xyz="0 0 0"/>
    <parent link="camera_depth_frame"/>
    <child link="camera_depth_optical_frame"/>
  </joint>

  <link name="camera_depth_optical_frame">
    <inertial>
        <mass value="0.0" />
        <origin xyz="0.0 0.0 0.0"/>
        <inertia ixx="0.0" ixy="0.0" ixz="0.0" iyy="0.0" iyz="0.0" izz="0.0" />
    </inertial>
  </link>
  

  <!-- camera left IR joints and links -->
  <joint name="camera_left_ir_joint" type="fixed">
    <origin rpy="0 0 0" xyz="0 0.0 0"/>
    <parent link="camera_depth_frame"/>
    <child link="camera_left_ir_frame"/>
  </joint>

  <link name="camera_left_ir_frame">
    <inertial>
        <mass value="0.0" />
        <origin xyz="0.0 0.0 0.0"/>
        <inertia ixx="0.0" ixy="0.0" ixz="0.0" iyy="0.0" iyz="0.0" izz="0.0" />
    </inertial>
  </link>

  <joint name="camera_left_ir_optical_joint" type="fixed">
    <origin rpy="-1.5707963267948966 0 -1.5707963267948966" xyz="0 0 0"/>
    <parent link="camera_left_ir_frame"/>
    <child link="camera_left_ir_optical_frame"/>
  </joint>

  <link name="camera_left_ir_optical_frame">
    <inertial>
        <mass value="0.0" />
        <origin xyz="0.0 0.0 0.0"/>
        <inertia ixx="0.0" ixy="0.0" ixz="0.0" iyy="0.0" iyz="0.0" izz="0.0" />
    </inertial>
  </link>

  <!-- camera right IR joints and links -->
  <joint name="camera_right_ir_joint" type="fixed">
    <origin rpy="0 0 0" xyz="0 -0.05 0"/>
    <parent link="camera_depth_frame"/>
    <child link="camera_right_ir_frame"/>
  </joint>

  <link name="camera_right_ir_frame">
    <inertial>
        <mass value="0.0" />
        <origin xyz="0.0 0.0 0.0"/>
        <inertia ixx="0.0" ixy="0.0" ixz="0.0" iyy="0.0" iyz="0.0" izz="0.0" />
    </inertial>
  </link>

  <joint name="camera_right_ir_optical_joint" type="fixed">
    <origin rpy="-1.5707963267948966 0 -1.5707963267948966" xyz="0 0 0"/>
    <parent link="camera_right_ir_frame"/>
    <child link="camera_right_ir_optical_frame"/>
  </joint>

  <link name="camera_right_ir_optical_frame">
    <inertial>
        <mass value="0.0" />
        <origin xyz="0.0 0.0 0.0"/>
        <inertia ixx="0.0" ixy="0.0" ixz="0.0" iyy="0.0" iyz="0.0" izz="0.0" />
    </inertial>
  </link>

  <!-- camera color joints and links -->
  <joint name="camera_color_joint" type="fixed">
    <origin rpy="0 0 0" xyz="0 0.015 0"/>
    <parent link="camera_depth_frame"/>
    <child link="camera_color_frame"/>
  </joint>

  <link name="camera_color_frame">
    <inertial>
        <mass value="0.0" />
        <origin xyz="0.0 0.0 0.0"/>
        <inertia ixx="0.0" ixy="0.0" ixz="0.0" iyy="0.0" iyz="0.0" izz="0.0" />
    </inertial>
  </link>

  <joint name="camera_color_optical_joint" type="fixed">
    <origin rpy="-1.5707963267948966 0 -1.5707963267948966" xyz="0 0 0"/>
    <parent link="camera_color_frame"/>
    <child link="camera_color_optical_frame"/>
  </joint>

  <link name="camera_color_optical_frame">
    <inertial>
        <mass value="0.0" />
        <origin xyz="0.0 0.0 0.0"/>
        <inertia ixx="0.0" ixy="0.0" ixz="0.0" iyy="0.0" iyz="0.0" izz="0.0" />
    </inertial>
  </link>


  <link name="ur_gripper">
    <visual>
      <geometry>
        <mesh filename="./stl/ur_gripper.stl" scale="0.001 0.001 0.001"/>
      </geometry>
      <material name="grey"/>
    </visual>
    <collision>
      <geometry>
        <mesh filename="./stl/ur_gripper.stl" scale="0.001 0.001 0.001"/>
      </geometry>
    </collision>
            <inertial>
            <mass value="0.1" />
            <origin xyz="0 0 0" rpy="0 0 0" />
            <inertia ixx="0.03" iyy="0.03" izz="0.03" ixy="0.0" ixz="0.0" iyz="0.0" />
        </inertial>
  </link>

  <joint name="camera_joint" type="fixed">
    <origin rpy="3.1414 0.0 1.5707" xyz="0.055 0.015 0.03"/>
    <parent link="ur_gripper"/>
    <child link="camera_bottom_screw_frame"/>
  </joint>
  <link name="camera_bottom_screw_frame">
    <inertial>
        <mass value="0.0" />
        <origin xyz="0.0 0.0 0.0"/>
        <inertia ixx="0.0" ixy="0.0" ixz="0.0" iyy="0.0" iyz="0.0" izz="0.0" />
    </inertial>
  </link>
  <joint name="camera_link_joint" type="fixed">
    <origin rpy="0 -0.4 0" xyz="0 0.0175 0.0125"/>   <!-- RPY: 0 0 0 -->
    <parent link="camera_bottom_screw_frame"/>
    <child link="camera_link"/>
  </joint>
  <joint name="ur_gripper_joint" type="fixed">
    <parent link="wrist_3_link"/>
    <child link="ur_gripper"/>
    <origin rpy="1.57 -0.0 -0.785" xyz="0.08423 0.161 -0.0"/>
  </joint>



  <link name="robotiq_finger_1_link_0">
        <visual>
            <origin rpy="0 0 0" xyz="0.020 0 0" />
            <geometry>
                <mesh filename="./robotiq_3f_description/meshes/robotiq-3f-gripper_articulated/visual/link_0.dae" />
            </geometry>
            <material name="gray">
                <color rgba="0.2 0.2 0.2 1" />
            </material>
        </visual>
        <collision>
            <origin rpy="0 0 0" xyz="0.020 0 0" />
            <geometry>
                <mesh filename="./robotiq_3f_description/meshes/robotiq-3f-gripper_articulated/collision/link_0.STL" />
            </geometry>
            <material name="yellow">
                <color rgba="0 1 1 1" />
            </material>
        </collision>
        <inertial>
            <origin rpy="0 0 0" xyz="0 0 0" />
            <mass value="0.05" />
            <inertia ixx="0.01" ixy="-0.00002" ixz="0.00001" iyy="0.0008" iyz="0" izz="0.001" />
        </inertial>
    </link>
    <link name="robotiq_finger_1_link_1">
        <visual>
            <origin rpy="0 0 -0.52" xyz="0.050 -.028 0" />
            <geometry>
                <mesh filename="./robotiq_3f_description/meshes/robotiq-3f-gripper_articulated/visual/link_1.dae" />
            </geometry>
            <material name="gray" />
        </visual>
        <collision>
            <origin rpy="0 0 -0.52" xyz="0.050 -.028 0" />
            <geometry>
                <mesh filename="./robotiq_3f_description/meshes/robotiq-3f-gripper_articulated/collision/link_1.STL" />
            </geometry>
            <material name="yellow" />
        </collision>
        <inertial>
            <origin rpy="0 0 0" xyz="0 0 0" />
            <mass value="0.15" />
            <inertia ixx="0.001859" ixy="-0.000376" ixz="0.000028" iyy="0.012756" iyz="0" izz="0.0024" />
        </inertial>
    </link>
    <link name="robotiq_finger_1_link_2">
        <!--
			NOTE: This link has an offset in the z-direction based on the models that were
			used to generate grap-it poses.  With the offset below the model appears visually
			correct, but it is suspect.
			-->
        <visual>
            <origin rpy="0 0 0" xyz="0.039 0 0.0075" />
            <geometry>
                <mesh filename="./robotiq_3f_description/meshes/robotiq-3f-gripper_articulated/visual/link_2.dae" />
            </geometry>
            <material name="gray" />
        </visual>
        <collision>
            <origin rpy="0 0 0" xyz="0.039 0 0.0075" />
            <geometry>
                <mesh filename="./robotiq_3f_description/meshes/robotiq-3f-gripper_articulated/collision/link_2.STL" />
            </geometry>
            <material name="yellow" />
        </collision>
        <inertial>
            <origin rpy="0 0 0" xyz="0 0 0" />
            <mass value="0.15" />
            <inertia ixx="0.001859" ixy="-0.000376" ixz="0.000028" iyy="0.012756" iyz="0" izz="0.0024" />
        </inertial>
    </link>
    <link name="robotiq_finger_1_link_3">
        <visual>
            <origin rpy="0 0 0.52" xyz="0 0 0" />
            <geometry>
                <mesh filename="./robotiq_3f_description/meshes/robotiq-3f-gripper_articulated/visual/link_3.dae" />
            </geometry>
            <material name="gray" />
        </visual>
        <collision>
            <origin rpy="0 0 0.52" xyz="0 0 0" />
            <geometry>
                <mesh filename="./robotiq_3f_description/meshes/robotiq-3f-gripper_articulated/collision/link_3.STL" />
            </geometry>
            <material name="yellow" />
        </collision>
        <inertial>
            <origin rpy="0 0 0" xyz="0 0 0" />
            <mass value="0.05" />
            <inertia ixx="0.001239" ixy="-0.000251" ixz="0.000019" iyy="0.00085" iyz="0" izz="0.001632" />
        </inertial>
    </link>
    <!-- end of link list -->
    <!-- joint list -->
    <joint name="robotiq_finger_1_joint_1" type="revolute">
        <parent link="robotiq_finger_1_link_0" />
        <child link="robotiq_finger_1_link_1" />
        <axis xyz="0 0 1" />
        <origin rpy="0 0 0" xyz="0.020 0 0" />
        <limit effort="100" lower="0.0495" upper="1.2218" velocity="100" />
    </joint>
    <joint name="robotiq_finger_1_joint_2" type="fixed">
        <parent link="robotiq_finger_1_link_1" />
        <child link="robotiq_finger_1_link_2" />
        <axis xyz="0 0 1" />
        <origin rpy="0 0 -0.52" xyz="0.050 -.028 0" />
        <limit effort="100" lower="0.0" upper="1.5708" velocity="100" />
    </joint>
    <joint name="robotiq_finger_1_joint_3" type="fixed">
        <parent link="robotiq_finger_1_link_2" />
        <child link="robotiq_finger_1_link_3" />
        <axis xyz="0 0 1" />
        <origin rpy="0 0 -0.6" xyz="0.039 0 0" />
        <limit effort="100" lower="-1.2217" upper="-0.0523" velocity="100" />
    </joint>
    <!-- end of joint list -->
    <!-- link list -->
    <link name="robotiq_finger_2_link_0">
        <visual>
            <origin rpy="0 0 0" xyz="0.020 0 0" />
            <geometry>
                <mesh filename="./robotiq_3f_description/meshes/robotiq-3f-gripper_articulated/visual/link_0.dae" />
            </geometry>
            <material name="gray">
                <color rgba="0.2 0.2 0.2 1" />
            </material>
        </visual>
        <collision>
            <origin rpy="0 0 0" xyz="0.020 0 0" />
            <geometry>
                <mesh filename="./robotiq_3f_description/meshes/robotiq-3f-gripper_articulated/collision/link_0.STL" />
            </geometry>
            <material name="yellow">
                <color rgba="0 1 1 1" />
            </material>
        </collision>
        <inertial>
            <origin rpy="0 0 0" xyz="0 0 0" />
            <mass value="0.05" />
            <inertia ixx="0.01" ixy="-0.00002" ixz="0.00001" iyy="0.0008" iyz="0" izz="0.001" />
        </inertial>
    </link>
    <link name="robotiq_finger_2_link_1">
        <visual>
            <origin rpy="0 0 -0.52" xyz="0.050 -.028 0" />
            <geometry>
                <mesh filename="./robotiq_3f_description/meshes/robotiq-3f-gripper_articulated/visual/link_1.dae" />
            </geometry>
            <material name="gray" />
        </visual>
        <collision>
            <origin rpy="0 0 -0.52" xyz="0.050 -.028 0" />
            <geometry>
                <mesh filename="./robotiq_3f_description/meshes/robotiq-3f-gripper_articulated/collision/link_1.STL" />
            </geometry>
            <material name="yellow" />
        </collision>
        <inertial>
            <origin rpy="0 0 0" xyz="0 0 0" />
            <mass value="0.15" />
            <inertia ixx="0.001859" ixy="-0.000376" ixz="0.000028" iyy="0.012756" iyz="0" izz="0.0024" />
        </inertial>
    </link>
    <link name="robotiq_finger_2_link_2">
        <!--
			NOTE: This link has an offset in the z-direction based on the models that were
			used to generate grap-it poses.  With the offset below the model appears visually
			correct, but it is suspect.
			-->
        <visual>
            <origin rpy="0 0 0" xyz="0.039 0 0.0075" />
            <geometry>
                <mesh filename="./robotiq_3f_description/meshes/robotiq-3f-gripper_articulated/visual/link_2.dae" />
            </geometry>
            <material name="gray" />
        </visual>
        <collision>
            <origin rpy="0 0 0" xyz="0.039 0 0.0075" />
            <geometry>
                <mesh filename="./robotiq_3f_description/meshes/robotiq-3f-gripper_articulated/collision/link_2.STL" />
            </geometry>
            <material name="yellow" />
        </collision>
        <inertial>
            <origin rpy="0 0 0" xyz="0 0 0" />
            <mass value="0.15" />
            <inertia ixx="0.001859" ixy="-0.000376" ixz="0.000028" iyy="0.012756" iyz="0" izz="0.0024" />
        </inertial>
    </link>
    <link name="robotiq_finger_2_link_3">
        <visual>
            <origin rpy="0 0 0.52" xyz="0 0 0" />
            <geometry>
                <mesh filename="./robotiq_3f_description/meshes/robotiq-3f-gripper_articulated/visual/link_3.dae" />
            </geometry>
            <material name="gray" />
        </visual>
        <collision>
            <origin rpy="0 0 0.52" xyz="0 0 0" />
            <geometry>
                <mesh filename="./robotiq_3f_description/meshes/robotiq-3f-gripper_articulated/collision/link_3.STL" />
            </geometry>
            <material name="yellow" />
        </collision>
        <inertial>
            <origin rpy="0 0 0" xyz="0 0 0" />
            <mass value="0.05" />
            <inertia ixx="0.001239" ixy="-0.000251" ixz="0.000019" iyy="0.00085" iyz="0" izz="0.001632" />
        </inertial>
    </link>
    <!-- end of link list -->
    <!-- joint list -->
    <joint name="robotiq_finger_2_joint_1" type="revolute">
        <parent link="robotiq_finger_2_link_0" />
        <child link="robotiq_finger_2_link_1" />
        <axis xyz="0 0 1" />
        <origin rpy="0 0 0" xyz="0.020 0 0" />
        <limit effort="100" lower="0.0495" upper="1.2218" velocity="100" />
    </joint>
    <joint name="robotiq_finger_2_joint_2" type="fixed">
        <parent link="robotiq_finger_2_link_1" />
        <child link="robotiq_finger_2_link_2" />
        <axis xyz="0 0 1" />
        <origin rpy="0 0 -0.52" xyz="0.050 -.028 0" />
        <limit effort="100" lower="0.0" upper="1.5708" velocity="100" />
    </joint>
    <joint name="robotiq_finger_2_joint_3" type="fixed">
        <parent link="robotiq_finger_2_link_2" />
        <child link="robotiq_finger_2_link_3" />
        <axis xyz="0 0 1" />
        <origin rpy="0 0 -0.6" xyz="0.039 0 0" />
        <limit effort="100" lower="-1.2217" upper="-0.0523" velocity="100" />
    </joint>
    <!-- end of joint list -->
    <!-- link list -->
    <link name="robotiq_finger_middle_link_0">
        <visual>
            <origin rpy="0 0 0" xyz="0.020 0 0" />
            <geometry>
                <mesh filename="./robotiq_3f_description/meshes/robotiq-3f-gripper_articulated/visual/link_0.dae" />
            </geometry>
            <material name="gray">
                <color rgba="0.2 0.2 0.2 1" />
            </material>
        </visual>
        <collision>
            <origin rpy="0 0 0" xyz="0.020 0 0" />
            <geometry>
                <mesh filename="./robotiq_3f_description/meshes/robotiq-3f-gripper_articulated/collision/link_0.STL" />
            </geometry>
            <material name="yellow">
                <color rgba="0 1 1 1" />
            </material>
        </collision>
        <inertial>
            <origin rpy="0 0 0" xyz="0 0 0" />
            <mass value="0.05" />
            <inertia ixx="0.01" ixy="-0.00002" ixz="0.00001" iyy="0.0008" iyz="0" izz="0.001" />
        </inertial>
    </link>
    <link name="robotiq_finger_middle_link_1">
        <visual>
            <origin rpy="0 0 -0.52" xyz="0.050 -.028 0" />
            <geometry>
                <mesh filename="./robotiq_3f_description/meshes/robotiq-3f-gripper_articulated/visual/link_1.dae" />
            </geometry>
            <material name="gray" />
        </visual>
        <collision>
            <origin rpy="0 0 -0.52" xyz="0.050 -.028 0" />
            <geometry>
                <mesh filename="./robotiq_3f_description/meshes/robotiq-3f-gripper_articulated/collision/link_1.STL" />
            </geometry>
            <material name="yellow" />
        </collision>
        <inertial>
            <origin rpy="0 0 0" xyz="0 0 0" />
            <mass value="0.15" />
            <inertia ixx="0.001859" ixy="-0.000376" ixz="0.000028" iyy="0.012756" iyz="0" izz="0.0024" />
        </inertial>
    </link>
    <link name="robotiq_finger_middle_link_2">
        <!--
			NOTE: This link has an offset in the z-direction based on the models that were
			used to generate grap-it poses.  With the offset below the model appears visually
			correct, but it is suspect.
			-->
        <visual>
            <origin rpy="0 0 0" xyz="0.039 0 0.0075" />
            <geometry>
                <mesh filename="./robotiq_3f_description/meshes/robotiq-3f-gripper_articulated/visual/link_2.dae" />
            </geometry>
            <material name="gray" />
        </visual>
        <collision>
            <origin rpy="0 0 0" xyz="0.039 0 0.0075" />
            <geometry>
                <mesh filename="./robotiq_3f_description/meshes/robotiq-3f-gripper_articulated/collision/link_2.STL" />
            </geometry>
            <material name="yellow" />
        </collision>
        <inertial>
            <origin rpy="0 0 0" xyz="0 0 0" />
            <mass value="0.15" />
            <inertia ixx="0.001859" ixy="-0.000376" ixz="0.000028" iyy="0.012756" iyz="0" izz="0.0024" />
        </inertial>
    </link>
    <link name="robotiq_finger_middle_link_3">
        <visual>
            <origin rpy="0 0 0.52" xyz="0 0 0" />
            <geometry>
                <mesh filename="./robotiq_3f_description/meshes/robotiq-3f-gripper_articulated/visual/link_3.dae" />
            </geometry>
            <material name="gray" />
        </visual>
        <collision>
            <origin rpy="0 0 0.52" xyz="0 0 0" />
            <geometry>
                <mesh filename="./robotiq_3f_description/meshes/robotiq-3f-gripper_articulated/collision/link_3.STL" />
            </geometry>
            <material name="yellow" />
        </collision>
        <inertial>
            <origin rpy="0 0 0" xyz="0 0 0" />
            <mass value="0.05" />
            <inertia ixx="0.001239" ixy="-0.000251" ixz="0.000019" iyy="0.00085" iyz="0" izz="0.001632" />
        </inertial>
    </link>
    <!-- end of link list -->
    <!-- joint list -->
    <joint name="robotiq_finger_middle_joint_1" type="revolute">
        <parent link="robotiq_finger_middle_link_0" />
        <child link="robotiq_finger_middle_link_1" />
        <axis xyz="0 0 1" />
        <origin rpy="0 0 0" xyz="0.020 0 0" />
        <limit effort="100" lower="0.0495" upper="1.2218" velocity="100" />
    </joint>
    <joint name="robotiq_finger_middle_joint_2" type="fixed">
        <parent link="robotiq_finger_middle_link_1" />
        <child link="robotiq_finger_middle_link_2" />
        <axis xyz="0 0 1" />
        <origin rpy="0 0 -0.52" xyz="0.050 -.028 0" />
        <limit effort="100" lower="0.0" upper="1.5708" velocity="100" />
    </joint>
    <joint name="robotiq_finger_middle_joint_3" type="fixed">
        <parent link="robotiq_finger_middle_link_2" />
        <child link="robotiq_finger_middle_link_3" />
        <axis xyz="0 0 1" />
        <origin rpy="0 0 -0.6" xyz="0.039 0 0" />
        <limit effort="100" lower="-1.2217" upper="-0.0523" velocity="100" />
    </joint>
    <!-- end of joint list -->
    <!-- link list -->
    <link name="robotiq_palm">
        <visual>
            <geometry>
                <mesh filename="./robotiq_3f_description/meshes/robotiq-3f-gripper_articulated/visual/palm.dae" />
            </geometry>
            <material name="gray">
                <color rgba="0.2 0.2 0.2 1" />
            </material>
        </visual>
        <collision>
            <geometry>
                <mesh filename="./robotiq_3f_description/meshes/robotiq-3f-gripper_articulated/collision/palm.STL" />
            </geometry>
            <material name="yellow">
                <color rgba="0 1 1 1" />
            </material>
        </collision>
        <inertial>
            <mass value="0.1" />
            <origin xyz="0 0 0" rpy="0 0 0" />
            <inertia ixx="0.03" iyy="0.03" izz="0.03" ixy="0.0" ixz="0.0" iyz="0.0" />
        </inertial>
    </link>
    <link name="robotiq_tool0" >
        <inertial>
            <origin rpy="0 0 0" xyz="0 0 0" />
            <mass value="1.3" />
            <inertia ixx="0.006012" ixy="0.000079" ixz="-0.00024" iyy="0.012892" iyz="0" izz="0.002435" />
        </inertial>
    </link>
    <!-- end of link list -->
    <!-- joint list -->
    <joint name="robotiq_palm_finger_1_joint" type="fixed">
        <parent link="robotiq_palm" />
        <child link="robotiq_finger_1_link_0" />
        <axis xyz="0 1 0" />
        <origin rpy="0 3.1416 -1.57" xyz="-0.0455 0.0214 0.036" />
        <limit effort="100" lower="-0.1784" upper="0.192" velocity="100" />
    </joint>
    <joint name="robotiq_palm_finger_2_joint" type="fixed">
        <parent link="robotiq_palm" />
        <child link="robotiq_finger_2_link_0" />
        <axis xyz="0 1 0" />
        <origin rpy="0 3.1416 -1.57" xyz="-0.0455 0.0214 -0.036" />
        <limit effort="100" lower="-0.192" upper="0.1784" velocity="100" />
    </joint>
    <joint name="robotiq_palm_finger_middle_joint" type="fixed">
        <parent link="robotiq_palm" />
        <child link="robotiq_finger_middle_link_0" />
        <axis xyz="0 0 1" />
        <origin rpy="0 0 1.57" xyz="0.0455 0.0214 0" />
    </joint>
    <joint name="robotiq_palm_tool0" type="fixed">
        <parent link="robotiq_palm" />
        <child link="robotiq_tool0" />
        <origin rpy="0 0 1.5707" xyz="0.0 0.0875 0.0" />
    </joint>
    <!-- end of joint list -->


  <joint name="urGripper_gripper_joint" type="fixed">
    <parent link="ur_gripper"/>
    <child link="robotiq_palm"/>
    <origin rpy="0.0 3.14 0.0" xyz="0.055 0.068 0.1735"/>
  </joint>

<!--   
  <link name="contact1">
    <visual>
      <geometry>
        <box size="0.008 0.1 0.027"/>
      </geometry>
    </visual>
    <collision>
        <geometry>
            <box size="0.008 0.1 0.027"/>
        </geometry>
    </collision>
    <inertial>
            <mass value="0.0" />
            <origin xyz="0 0 0" rpy="0 0 0" />
            <inertia ixx="0.0" iyy="0.0" izz="0.0" ixy="0.0" ixz="0.0" iyz="0.0" />
        </inertial>
  </link>
  <joint name="contact1_finger1" type="fixed">
    <parent link="robotiq_finger_middle_link_3"/>
    <child link="contact1"/>
    <origin  xyz="-0.018 -0.0075 0.0" rpy="0.0 0.0 2.21"/> 
  </joint>

  <link name="contact2">
    <visual>
      <geometry>
        <box size="0.008 0.1 0.027"/>
      </geometry>
    </visual>
    <collision>
        <geometry>
            <box size="0.008 0.1 0.027"/>
        </geometry>
    </collision>
    <inertial>
            <mass value="0.0" />
            <origin xyz="0 0 0" rpy="0 0 0" />
            <inertia ixx="0.0" iyy="0.0" izz="0.0" ixy="0.0" ixz="0.0" iyz="0.0" />
        </inertial>
  </link>
  <joint name="contact2_finger1" type="fixed">
    <parent link="robotiq_finger_1_link_3"/>
    <child link="contact2"/>
    <origin  xyz="-0.018 -0.0075 0.0" rpy="0.0 0.0 2.21"/> 
  </joint>

  <link name="contact3">
    <visual>
      <geometry>
        <box size="0.008 0.1 0.027"/>
      </geometry>
    </visual>
    <collision>
        <geometry>
            <box size="0.008 0.1 0.027"/>
        </geometry>
    </collision>
    <inertial>
            <mass value="0.0" />
            <origin xyz="0 0 0" rpy="0 0 0" />
            <inertia ixx="0.0" iyy="0.0" izz="0.0" ixy="0.0" ixz="0.0" iyz="0.0" />
        </inertial>
  </link>
  <joint name="contact3_finger1" type="fixed">
    <parent link="robotiq_finger_2_link_3"/>
    <child link="contact3"/>
    <origin  xyz="-0.018 -0.0075 0.0" rpy="0.0 0.0 2.21"/> 
  </joint> -->






</robot>

  <!-- <link name="robotiq_tool0"/>

  <joint name="robotiq_palm_tool0" type="fixed">
    <parent link="robotiq_palm"/>
    <child link="robotiq_tool0"/>
    <origin rpy="0 0 1.5707" xyz="0.0 0.0875 0.0"/>
  </joint> -->

<!-- <link name="ur_gripper">
    <visual>
      <geometry>
        <mesh filename="./stl/ur_gripper.stl" scale="0.001 0.001 0.001"/>
      </geometry>
      <material name="grey"/>
    </visual>
    <collision>
      <geometry>
        <mesh filename="./stl/ur_gripper.stl" scale="0.001 0.001 0.001"/>
      </geometry>
    </collision>
            <inertial>
            <mass value="0.1" />
            <origin xyz="0 0 0" rpy="0 0 0" />
            <inertia ixx="0.03" iyy="0.03" izz="0.03" ixy="0.0" ixz="0.0" iyz="0.0" />
        </inertial>
  </link> -->

  <!-- <joint name="camera_joint" type="fixed">
    <origin rpy="3.1414 0.0 1.5707" xyz="0.055 0.015 0.03"/>
    <parent link="ur_gripper"/>
    <child link="camera_bottom_screw_frame"/>
  </joint>
  <link name="camera_bottom_screw_frame"/>
  <joint name="camera_link_joint" type="fixed">
    <origin rpy="0 0 0" xyz="0 0.0175 0.0125"/>
    <parent link="camera_bottom_screw_frame"/>
    <child link="camera_link"/>
  </joint>
  <joint name="ur_gripper_joint" type="fixed">
    <parent link="wrist_3_link"/>
    <child link="ur_gripper"/>
    <origin rpy="1.57 -0.0 -0.785" xyz="0.08423 0.161 -0.0"/>
  </joint>
  <joint name="urGripper_gripper_joint" type="fixed">
    <parent link="ur_gripper"/>
    <child link="robotiq_palm"/>
    <origin rpy="0.0 3.14 0.0" xyz="0.055 0.068 0.1735"/>
  </joint> -->

  
    



